<?xml version="1.0" ?>
<!-- =================================================================================== -->
<!-- |    This document was autogenerated by xacro from drone.urdf.xacro               | -->
<!-- |    EDITING THIS FILE BY HAND IS NOT RECOMMENDED                                 | -->
<!-- =================================================================================== -->
<robot name="drone">
  <material name="frame_material">
    <color rgba="1 0.2 0.2 1"/>
  </material>
  <material name="arm_material">
    <color rgba="0.8 0.8 0.8 1"/>
  </material>
  <material name="propeller_material">
    <color rgba="0 0 0 0.6"/>
  </material>
  <link name="frame">
    <visual>
      <origin rpy="0 0 0" xyz="0 0 0"/>
      <geometry>
        <cylinder length="0.05" radius="0.1"/>
      </geometry>
      <material name="frame_material">
        <color rgba="0.8 0.8 0.8 1.0"/>
      </material>
    </visual>
    <collision>
      <origin rpy="0 0 0" xyz="0 0 0"/>
      <geometry>
        <cylinder length="0.05" radius="0.1"/>
      </geometry>
    </collision>
    <inertial>
      <mass value="0.88"/>
      <origin rpy="0 0 0" xyz="0 0 0"/>
      <inertia ixx="0.002383332380000001" ixy="0.0" ixz="0.0" iyy="0.002383332380000001" iyz="0.0" izz="0.0044"/>
    </inertial>
  </link>
  <gazebo reference="frame">
    <material>Gazebo/Orange</material>
  </gazebo>
  <link name="arm1">
    <visual>
      <origin rpy="0 1.5707963267948966 0.5235987755982988" xyz="0.15155444566227677 0.08749999999999998 0.015000000000000001"/>
      <geometry>
        <cylinder length="0.15" radius="0.01"/>
      </geometry>
      <material name="arm_material"/>
    </visual>
    <collision>
      <origin rpy="0 1.5707963267948966 0.5235987755982988" xyz="0.15155444566227677 0.08749999999999998 0.015000000000000001"/>
      <geometry>
        <cylinder length="0.15" radius="0.01"/>
      </geometry>
    </collision>
    <inertial>
      <mass value="0.01"/>
      <origin rpy="0 1.5707963267948966 0.5235987755982988" xyz="0.15155444566227677 0.08749999999999998 0.015000000000000001"/>
      <inertia ixx="1.8999992400000002e-05" ixy="0.0" ixz="0.0" iyy="1.8999992400000002e-05" iyz="0.0" izz="5.000000000000001e-07"/>
    </inertial>
  </link>
  <joint name="frame_arm1" type="fixed">
    <parent link="frame"/>
    <child link="arm1"/>
  </joint>
  <gazebo reference="arm1">
    <material>Gazebo/Grey</material>
  </gazebo>
  <link name="arm2">
    <visual>
      <origin rpy="0 1.5707963267948966 1.5707963267948966" xyz="1.071565949253934e-17 0.175 0.015000000000000001"/>
      <geometry>
        <cylinder length="0.15" radius="0.01"/>
      </geometry>
      <material name="arm_material"/>
    </visual>
    <collision>
      <origin rpy="0 1.5707963267948966 1.5707963267948966" xyz="1.071565949253934e-17 0.175 0.015000000000000001"/>
      <geometry>
        <cylinder length="0.15" radius="0.01"/>
      </geometry>
    </collision>
    <inertial>
      <mass value="0.01"/>
      <origin rpy="0 1.5707963267948966 1.5707963267948966" xyz="1.071565949253934e-17 0.175 0.015000000000000001"/>
      <inertia ixx="1.8999992400000002e-05" ixy="0.0" ixz="0.0" iyy="1.8999992400000002e-05" iyz="0.0" izz="5.000000000000001e-07"/>
    </inertial>
  </link>
  <joint name="frame_arm2" type="fixed">
    <parent link="frame"/>
    <child link="arm2"/>
  </joint>
  <gazebo reference="arm2">
    <material>Gazebo/Grey</material>
  </gazebo>
  <link name="arm3">
    <visual>
      <origin rpy="0 1.5707963267948966 2.617993877991494" xyz="-0.15155444566227672 0.08750000000000005 0.015000000000000001"/>
      <geometry>
        <cylinder length="0.15" radius="0.01"/>
      </geometry>
      <material name="arm_material"/>
    </visual>
    <collision>
      <origin rpy="0 1.5707963267948966 2.617993877991494" xyz="-0.15155444566227672 0.08750000000000005 0.015000000000000001"/>
      <geometry>
        <cylinder length="0.15" radius="0.01"/>
      </geometry>
    </collision>
    <inertial>
      <mass value="0.01"/>
      <origin rpy="0 1.5707963267948966 2.617993877991494" xyz="-0.15155444566227672 0.08750000000000005 0.015000000000000001"/>
      <inertia ixx="1.8999992400000002e-05" ixy="0.0" ixz="0.0" iyy="1.8999992400000002e-05" iyz="0.0" izz="5.000000000000001e-07"/>
    </inertial>
  </link>
  <joint name="frame_arm3" type="fixed">
    <parent link="frame"/>
    <child link="arm3"/>
  </joint>
  <gazebo reference="arm3">
    <material>Gazebo/Grey</material>
  </gazebo>
  <link name="arm4">
    <visual>
      <origin rpy="0 1.5707963267948966 3.665191429188092" xyz="-0.15155444566227677 -0.08749999999999995 0.015000000000000001"/>
      <geometry>
        <cylinder length="0.15" radius="0.01"/>
      </geometry>
      <material name="arm_material"/>
    </visual>
    <collision>
      <origin rpy="0 1.5707963267948966 3.665191429188092" xyz="-0.15155444566227677 -0.08749999999999995 0.015000000000000001"/>
      <geometry>
        <cylinder length="0.15" radius="0.01"/>
      </geometry>
    </collision>
    <inertial>
      <mass value="0.01"/>
      <origin rpy="0 1.5707963267948966 3.665191429188092" xyz="-0.15155444566227677 -0.08749999999999995 0.015000000000000001"/>
      <inertia ixx="1.8999992400000002e-05" ixy="0.0" ixz="0.0" iyy="1.8999992400000002e-05" iyz="0.0" izz="5.000000000000001e-07"/>
    </inertial>
  </link>
  <joint name="frame_arm4" type="fixed">
    <parent link="frame"/>
    <child link="arm4"/>
  </joint>
  <gazebo reference="arm4">
    <material>Gazebo/Grey</material>
  </gazebo>
  <link name="arm5">
    <visual>
      <origin rpy="0 1.5707963267948966 4.71238898038469" xyz="-3.214697847761802e-17 -0.175 0.015000000000000001"/>
      <geometry>
        <cylinder length="0.15" radius="0.01"/>
      </geometry>
      <material name="arm_material"/>
    </visual>
    <collision>
      <origin rpy="0 1.5707963267948966 4.71238898038469" xyz="-3.214697847761802e-17 -0.175 0.015000000000000001"/>
      <geometry>
        <cylinder length="0.15" radius="0.01"/>
      </geometry>
    </collision>
    <inertial>
      <mass value="0.01"/>
      <origin rpy="0 1.5707963267948966 4.71238898038469" xyz="-3.214697847761802e-17 -0.175 0.015000000000000001"/>
      <inertia ixx="1.8999992400000002e-05" ixy="0.0" ixz="0.0" iyy="1.8999992400000002e-05" iyz="0.0" izz="5.000000000000001e-07"/>
    </inertial>
  </link>
  <joint name="frame_arm5" type="fixed">
    <parent link="frame"/>
    <child link="arm5"/>
  </joint>
  <gazebo reference="arm5">
    <material>Gazebo/Grey</material>
  </gazebo>
  <link name="arm6">
    <visual>
      <origin rpy="0 1.5707963267948966 5.759586531581288" xyz="0.15155444566227677 -0.08749999999999994 0.015000000000000001"/>
      <geometry>
        <cylinder length="0.15" radius="0.01"/>
      </geometry>
      <material name="arm_material"/>
    </visual>
    <collision>
      <origin rpy="0 1.5707963267948966 5.759586531581288" xyz="0.15155444566227677 -0.08749999999999994 0.015000000000000001"/>
      <geometry>
        <cylinder length="0.15" radius="0.01"/>
      </geometry>
    </collision>
    <inertial>
      <mass value="0.01"/>
      <origin rpy="0 1.5707963267948966 5.759586531581288" xyz="0.15155444566227677 -0.08749999999999994 0.015000000000000001"/>
      <inertia ixx="1.8999992400000002e-05" ixy="0.0" ixz="0.0" iyy="1.8999992400000002e-05" iyz="0.0" izz="5.000000000000001e-07"/>
    </inertial>
  </link>
  <joint name="frame_arm6" type="fixed">
    <parent link="frame"/>
    <child link="arm6"/>
  </joint>
  <gazebo reference="arm6">
    <material>Gazebo/Grey</material>
  </gazebo>
  <link name="propeller1">
    <visual>
      <origin rpy="0 0 0" xyz="0 0 0"/>
      <geometry>
        <cylinder length="0.01" radius="0.1"/>
      </geometry>
      <material name="propeller_material"/>
    </visual>
    <collision>
      <origin rpy="0 0 0" xyz="0 0 0"/>
      <geometry>
        <cylinder length="0.01" radius="0.1"/>
      </geometry>
    </collision>
    <inertial>
      <mass value="0.01"/>
      <origin rpy="0 0 0" xyz="0 0 0"/>
      <inertia ixx="2.5083323300000005e-05" ixy="0.0" ixz="0.0" iyy="2.5083323300000005e-05" iyz="0.0" izz="5e-05"/>
    </inertial>
  </link>
  <joint name="arm1_propeller1" type="revolute">
    <parent link="arm1"/>
    <child link="propeller1"/>
    <origin rpy="0 0 0" xyz="0.21650635094610968 0.12499999999999999 0.04"/>
    <axis xyz="0 0 1"/>
    <limit effort="0" lower="0" upper="0" velocity="0"/>
  </joint>
  <gazebo reference="propeller1">
    <material>Gazebo/RedTransparent</material>
  </gazebo>
  <link name="propeller2">
    <visual>
      <origin rpy="0 0 0" xyz="0 0 0"/>
      <geometry>
        <cylinder length="0.01" radius="0.1"/>
      </geometry>
      <material name="propeller_material"/>
    </visual>
    <collision>
      <origin rpy="0 0 0" xyz="0 0 0"/>
      <geometry>
        <cylinder length="0.01" radius="0.1"/>
      </geometry>
    </collision>
    <inertial>
      <mass value="0.01"/>
      <origin rpy="0 0 0" xyz="0 0 0"/>
      <inertia ixx="2.5083323300000005e-05" ixy="0.0" ixz="0.0" iyy="2.5083323300000005e-05" iyz="0.0" izz="5e-05"/>
    </inertial>
  </link>
  <joint name="arm2_propeller2" type="revolute">
    <parent link="arm2"/>
    <child link="propeller2"/>
    <origin rpy="0 0 0" xyz="1.5308084989341915e-17 0.25 0.04"/>
    <axis xyz="0 0 1"/>
    <limit effort="0" lower="0" upper="0" velocity="0"/>
  </joint>
  <gazebo reference="propeller2">
    <material>Gazebo/BlackTransparent</material>
  </gazebo>
  <link name="propeller3">
    <visual>
      <origin rpy="0 0 0" xyz="0 0 0"/>
      <geometry>
        <cylinder length="0.01" radius="0.1"/>
      </geometry>
      <material name="propeller_material"/>
    </visual>
    <collision>
      <origin rpy="0 0 0" xyz="0 0 0"/>
      <geometry>
        <cylinder length="0.01" radius="0.1"/>
      </geometry>
    </collision>
    <inertial>
      <mass value="0.01"/>
      <origin rpy="0 0 0" xyz="0 0 0"/>
      <inertia ixx="2.5083323300000005e-05" ixy="0.0" ixz="0.0" iyy="2.5083323300000005e-05" iyz="0.0" izz="5e-05"/>
    </inertial>
  </link>
  <joint name="arm3_propeller3" type="revolute">
    <parent link="arm3"/>
    <child link="propeller3"/>
    <origin rpy="0 0 0" xyz="-0.21650635094610962 0.12500000000000008 0.04"/>
    <axis xyz="0 0 1"/>
    <limit effort="0" lower="0" upper="0" velocity="0"/>
  </joint>
  <gazebo reference="propeller3">
    <material>Gazebo/BlueTransparent</material>
  </gazebo>
  <link name="propeller4">
    <visual>
      <origin rpy="0 0 0" xyz="0 0 0"/>
      <geometry>
        <cylinder length="0.01" radius="0.1"/>
      </geometry>
      <material name="propeller_material"/>
    </visual>
    <collision>
      <origin rpy="0 0 0" xyz="0 0 0"/>
      <geometry>
        <cylinder length="0.01" radius="0.1"/>
      </geometry>
    </collision>
    <inertial>
      <mass value="0.01"/>
      <origin rpy="0 0 0" xyz="0 0 0"/>
      <inertia ixx="2.5083323300000005e-05" ixy="0.0" ixz="0.0" iyy="2.5083323300000005e-05" iyz="0.0" izz="5e-05"/>
    </inertial>
  </link>
  <joint name="arm4_propeller4" type="revolute">
    <parent link="arm4"/>
    <child link="propeller4"/>
    <origin rpy="0 0 0" xyz="-0.2165063509461097 -0.12499999999999993 0.04"/>
    <axis xyz="0 0 1"/>
    <limit effort="0" lower="0" upper="0" velocity="0"/>
  </joint>
  <gazebo reference="propeller4">
    <material>Gazebo/BlueTransparent</material>
  </gazebo>
  <link name="propeller5">
    <visual>
      <origin rpy="0 0 0" xyz="0 0 0"/>
      <geometry>
        <cylinder length="0.01" radius="0.1"/>
      </geometry>
      <material name="propeller_material"/>
    </visual>
    <collision>
      <origin rpy="0 0 0" xyz="0 0 0"/>
      <geometry>
        <cylinder length="0.01" radius="0.1"/>
      </geometry>
    </collision>
    <inertial>
      <mass value="0.01"/>
      <origin rpy="0 0 0" xyz="0 0 0"/>
      <inertia ixx="2.5083323300000005e-05" ixy="0.0" ixz="0.0" iyy="2.5083323300000005e-05" iyz="0.0" izz="5e-05"/>
    </inertial>
  </link>
  <joint name="arm5_propeller5" type="revolute">
    <parent link="arm5"/>
    <child link="propeller5"/>
    <origin rpy="0 0 0" xyz="-4.592425496802574e-17 -0.25 0.04"/>
    <axis xyz="0 0 1"/>
    <limit effort="0" lower="0" upper="0" velocity="0"/>
  </joint>
  <gazebo reference="propeller5">
    <material>Gazebo/BlackTransparent</material>
  </gazebo>
  <link name="propeller6">
    <visual>
      <origin rpy="0 0 0" xyz="0 0 0"/>
      <geometry>
        <cylinder length="0.01" radius="0.1"/>
      </geometry>
      <material name="propeller_material"/>
    </visual>
    <collision>
      <origin rpy="0 0 0" xyz="0 0 0"/>
      <geometry>
        <cylinder length="0.01" radius="0.1"/>
      </geometry>
    </collision>
    <inertial>
      <mass value="0.01"/>
      <origin rpy="0 0 0" xyz="0 0 0"/>
      <inertia ixx="2.5083323300000005e-05" ixy="0.0" ixz="0.0" iyy="2.5083323300000005e-05" iyz="0.0" izz="5e-05"/>
    </inertial>
  </link>
  <joint name="arm6_propeller6" type="revolute">
    <parent link="arm6"/>
    <child link="propeller6"/>
    <origin rpy="0 0 0" xyz="0.2165063509461097 -0.12499999999999992 0.04"/>
    <axis xyz="0 0 1"/>
    <limit effort="0" lower="0" upper="0" velocity="0"/>
  </joint>
  <gazebo reference="propeller6">
    <material>Gazebo/RedTransparent</material>
  </gazebo>

  <!-- Joint connecting Base Link to Depth Camera -->
  <joint name="camera_joint" type="revolute">
    <parent link="frame" />
    <child link="depth_camera" />
		<origin xyz="0 0 0.05" rpy="0 0 0" />
		<axis xyz="0 1 0" /> 
		<limit lower="-3.14159" upper="3.14159" effort="10" velocity="3.14159" /> 
  </joint>


<!-- Link: Depth Camera -->
<link name="depth_camera">
  <visual>
    <geometry>
      <box size="0.05 0.05 0.05" /> 
    </geometry>
  </visual>
  <collision>
    <geometry>
      <box size="0.05 0.05 0.05" />
    </geometry>
  </collision>
  <inertial>
    <mass value="0.01" />
    <origin rpy="0 0 0" xyz="0 0 0" />
    <inertia ixx="0.01" ixy="0.01" ixz="0.01" iyy="0.01" iyz="0.01" izz="0.01" />
  </inertial>
  <material name="camera_color">
    <color rgba="0 0 0 1"/>
  </material>
</link>

  <gazebo reference="frame">
  <sensor name="frame_camera" type="depth">
    <update_rate>20</update_rate>
    <camera>
      <horizontal_fov>1.047198</horizontal_fov>
      <image>
        <width>640</width>
        <height>480</height>
        <format>R8G8B8</format>
      </image>
      <clip>
        <near>0.05</near>
        <far>3</far>
      </clip>
    </camera>
    <plugin name="frame_controller" filename="libgazebo_ros_openni_kinect.so">
      <baseline>0.2</baseline>
      <alwaysOn>true</alwaysOn>
      <updateRate>1.0</updateRate>
      <cameraName>depth_camera_ir</cameraName>
      <imageTopicName>/depth_camera/color/image_raw</imageTopicName>
      <cameraInfoTopicName>/depth_camera/color/camera_info</cameraInfoTopicName>
      <depthImageTopicName>/depth_camera/depth/image_raw</depthImageTopicName>
      <depthImageInfoTopicName>/depth_camera/depth/camera_info</depthImageInfoTopicName>
      <pointCloudTopicName>/depth_camera/depth/points</pointCloudTopicName>
      <frameName>frame</frameName>
      <pointCloudCutoff>0.5</pointCloudCutoff>
      <pointCloudCutoffMax>3.0</pointCloudCutoffMax>
      <distortionK1>0.00000001</distortionK1>
      <distortionK2>0.00000001</distortionK2>
      <distortionK3>0.00000001</distortionK3>
      <distortionT1>0.00000001</distortionT1>
      <distortionT2>0.00000001</distortionT2>
      <CxPrime>0</CxPrime>
      <Cx>0</Cx>
      <Cy>0</Cy>
      <focalLength>0</focalLength>
      <hackBaseline>0</hackBaseline>
    </plugin>
  </sensor>
</gazebo>
</robot>

